Workbook

Sheet Log
A1: Date Bought | B1: Date Sold | C1: Item Description | D1: Cost | E1: Listing Price | F1: Sold For | G1: Prediction Profit | H1: Actual Profit | I1: Predicted Margin | J1: Actual margin | K1: Days to sell | L1: Status | M1: Proftit/Day | O1: mont sold | P1: month | Q1: profit that month
A2: 45944 | B2: 45951 | C2: drop leaf Table with 2 chairs | D2: 36 | F2: 225 | G2: =IF(ISNUMBER(H2),0,E2-D2) -> 0 | H2: =F2-D2 -> 189 | J2: =((F2-D2)/F2) -> 0.84 | K2: =IF(B2="",,B2-A2) -> 7 | L2: =IF(B2="","Listed","Sold") -> Sold | M2: =IF(L2="SOLD",H2/K2) -> 27 | O2: =MONTH(B2) -> 10 | P2: 10 | Q2: =SUMIF(O:O,P2,H:H) -> 831
A3: 45944 | B3: 45945 | C3: Coffee table | D3: 18 | E3: 100 | F3: 150 | G3: =IF(ISNUMBER(H3),0,E3-D3) -> 0 | H3: =F3-D3 -> 132 | J3: =((F3-D3)/F3) -> 0.88 | K3: =IF(B3="",,B3-A3) -> 1 | L3: =IF(B3="","Listed","Sold") -> Sold | M3: =IF(L3="SOLD",H3/K3) -> 132 | O3: =MONTH(B3) -> 10 | P3: 11 | Q3: =SUMIF(O:O,P3,H:H) -> 1468
A4: 45949 | B4: 45955 | C4: White desk | D4: 30 | E4: 100 | F4: 100 | G4: =IF(ISNUMBER(H4),0,E4-D4) -> 0 | H4: =IF(F4-D4<-1,"",F4-D4) -> 70 | I4: =G4/E4 -> 0 | J4: =((F4-D4)/F4) -> 0.7 | K4: =IF(B4="",,B4-A4) -> 6 | L4: =IF(B4="","Listed","Sold") -> Sold | M4: =IF(L4="SOLD",H4/K4) -> 11.666667 | O4: =MONTH(B4) -> 10 | P4: 12
A5: 45944 | B5: 46009 | C5: bar stools | D5: 35 | E5: 150 | F5: 100 | G5: =IF(ISNUMBER(H5),0,E5-D5) -> 0 | H5: =IF(F5-D5<-1,"",F5-D5) -> 65 | I5: =G5/E5 -> 0 | J5: =((F5-D5)/F5) -> 0.65 | K5: =IF(B5="",,B5-A5) -> 65 | L5: =IF(B5="","Listed","Sold") -> Sold | M5: =IF(L5="SOLD",H5/K5,"") -> 1 | O5: =MONTH(B5) -> 12
A6: 45949 | B6: 45956 | C6: Table/4 charis - Has insert | D6: 38 | E6: 275 | F6: 225 | G6: =IF(ISNUMBER(H6),0,E6-D6) -> 0 | H6: =IF(F6-D6<-1,"",F6-D6) -> 187 | I6: =G6/E6 -> 0 | J6: =((F6-D6)/F6) -> 0.83111111 | K6: =IF(B6="",,B6-A6) -> 7 | L6: =IF(B6="","Listed","Sold") -> Sold | M6: =IF(L6="SOLD",H6/K6,"") -> 26.714286 | O6: =MONTH(B6) -> 10
A7: 45944 | B7: 45953 | C7: Scalloped coffee table | D7: 42 | E7: 100 | F7: 100 | G7: =IF(ISNUMBER(H7),0,E7-D7) -> 0 | H7: =IF(F7-D7<-1,"",F7-D7) -> 58 | I7: =G7/E7 -> 0 | J7: =((F7-D7)/F7) -> 0.58 | K7: =IF(B7="",,B7-A7) -> 9 | L7: =IF(B7="","Listed","Sold") -> Sold | M7: =IF(L7="SOLD",H7/K7,"") -> 6.4444444 | O7: =MONTH(B7) -> 10
A8: 45952 | B8: 45955 | C8: Table dark top white legs | D8: 45 | E8: 225 | F8: 200 | G8: =IF(ISNUMBER(H8),0,E8-D8) -> 0 | H8: =IF(F8-D8<-1,"",F8-D8) -> 155 | I8: =G8/E8 -> 0 | J8: =((F8-D8)/F8) -> 0.775 | K8: =IF(B8="",,B8-A8) -> 3 | L8: =IF(B8="","Listed","Sold") -> Sold | M8: =IF(L8="SOLD",H8/K8,"") -> 51.666667 | O8: =MONTH(B8) -> 10
A9: 45952 | B9: 45986 | C9: Chair | D9: 12 | E9: 50 | F9: 40 | G9: =IF(ISNUMBER(H9),0,E9-D9) -> 0 | H9: =IF(F9-D9<-1,"",F9-D9) -> 28 | I9: =G9/E9 -> 0 | J9: =((F9-D9)/F9) -> 0.7 | K9: =IF(B9="",,B9-A9) -> 34 | L9: =IF(B9="","Listed","Sold") -> Sold | M9: =IF(L9="SOLD",H9/K9,"") -> 0.82352941 | O9: =MONTH(B9) -> 11
A10: 45952 | B10: 45952 | C10: Furniture Restorer | D10: 10 | E10: 0 | G10: =IF(ISNUMBER(H10),0,E10-D10) -> -10 | H10: =IF(F10-D10<-1,"",F10-D10) | I10: =G10/E10 -> #DIV/0! | J10: =((F10-D10)/F10) -> #DIV/0! | K10: =IF(B10="",,B10-A10) -> 0 | L10: =IF(B10="","Listed","Sold") -> Sold | M10: =IF(L10="SOLD",H10/K10,"") -> #VALUE! | O10: =MONTH(B10) -> 10
A11: 45956 | B11: 45967 | C11: dark side table | D11: 8 | E11: 100 | F11: 60 | G11: =IF(ISNUMBER(H11),0,E11-D11) -> 0 | H11: =IF(F11-D11<-1,"",F11-D11) -> 52 | I11: =G11/E11 -> 0 | J11: =((F11-D11)/F11) -> 0.86666667 | K11: =IF(B11="",,B11-A11) -> 11 | L11: =IF(B11="","Listed","Sold") -> Sold | M11: =IF(L11="SOLD",H11/K11,"") -> 4.7272727 | O11: =MONTH(B11) -> 11
A12: 45956 | B12: 45968 | C12: mini table | D12: 6 | E12: 25 | F12: 25 | G12: =IF(ISNUMBER(H12),0,E12-D12) -> 0 | H12: =IF(F12-D12<-1,"",F12-D12) -> 19 | I12: =G12/E12 -> 0 | J12: =((F12-D12)/F12) -> 0.76 | K12: =IF(B12="",,B12-A12) -> 12 | L12: =IF(B12="","Listed","Sold") -> Sold | M12: =IF(L12="SOLD",H12/K12,"") -> 1.5833333 | O12: =MONTH(B12) -> 11
A13: 45957 | B13: 45961 | C13: lamp | D13: 10 | E13: 50 | F13: 50 | G13: =IF(ISNUMBER(H13),0,E13-D13) -> 0 | H13: =IF(F13-D13<-1,"",F13-D13) -> 40 | I13: =G13/E13 -> 0 | J13: =((F13-D13)/F13) -> 0.8 | K13: =IF(B13="",,B13-A13) -> 4 | L13: =IF(B13="","Listed","Sold") -> Sold | M13: =IF(L13="SOLD",H13/K13,"") -> 10 | O13: =MONTH(B13) -> 10
A14: 45959 | B14: 45969 | C14: Bench | D14: 28 | E14: 50 | F14: 125 | G14: =IF(ISNUMBER(H14),0,E14-D14) -> 0 | H14: =IF(F14-D14<-1,"",F14-D14) -> 97 | I14: =G14/E14 -> 0 | J14: =((F14-D14)/F14) -> 0.776 | K14: =IF(B14="",,B14-A14) -> 10 | L14: =IF(B14="","Listed","Sold") -> Sold | M14: =IF(L14="SOLD",H14/K14,"") -> 9.7 | O14: =MONTH(B14) -> 11
A15: 45959 | B15: 45969 | C15: little table with drawer | D15: 18 | E15: 50 | F15: 40 | G15: =IF(ISNUMBER(H15),0,E15-D15) -> 0 | H15: =IF(F15-D15<-1,"",F15-D15) -> 22 | I15: =G15/E15 -> 0 | J15: =((F15-D15)/F15) -> 0.55 | K15: =IF(B15="",,B15-A15) -> 10 | L15: =IF(B15="","Listed","Sold") -> Sold | M15: =IF(L15="SOLD",H15/K15,"") -> 2.2 | O15: =MONTH(B15) -> 11
A16: 45959 | B16: 45962 | C16: Drop leaf table chairs 4 | D16: 75 | E16: 400 | F16: 280 | G16: =IF(ISNUMBER(H16),0,E16-D16) -> 0 | H16: =IF(F16-D16<-1,"",F16-D16) -> 205 | I16: =G16/E16 -> 0 | J16: =((F16-D16)/F16) -> 0.73214286 | K16: =IF(B16="",,B16-A16) -> 3 | L16: =IF(B16="","Listed","Sold") -> Sold | M16: =IF(L16="SOLD",H16/K16,"") -> 68.333333 | O16: =MONTH(B16) -> 11
A17: 45959 | B17: 45970 | C17: drop leaf table with chairs | D17: 10 | E17: 250 | F17: 95 | G17: =IF(ISNUMBER(H17),0,E17-D17) -> 0 | H17: =IF(F17-D17<-1,"",F17-D17) -> 85 | I17: =G17/E17 -> 0 | J17: =((F17-D17)/F17) -> 0.89473684 | K17: =IF(B17="",,B17-A17) -> 11 | L17: =IF(B17="","Listed","Sold") -> Sold | M17: =IF(L17="SOLD",H17/K17,"") -> 7.7272727 | O17: =MONTH(B17) -> 11
A18: 45959 | B18: 46028 | C18: feathen Allen | D18: 0 | F18: 60 | G18: =IF(ISNUMBER(H18),0,E18-D18) -> 0 | H18: =IF(F18-D18<-1,"",F18-D18) -> 60 | I18: =G18/E18 -> #DIV/0! | J18: =((F18-D18)/F18) -> 1 | K18: =IF(B18="",,B18-A18) -> 69 | L18: =IF(B18="","Listed","Sold") -> Sold | M18: =IF(L18="SOLD",H18/K18,"") -> 0.86956522 | O18: =MONTH(B18) -> 1
A19: 45959 | B19: 45966 | C19: eathan allen chairs 3 | D19: 15 | E19: 150 | F19: 150 | G19: =IF(ISNUMBER(H19),0,E19-D19) -> 0 | H19: =IF(F19-D19<-1,"",F19-D19) -> 135 | I19: =G19/E19 -> 0 | J19: =((F19-D19)/F19) -> 0.9 | K19: =IF(B19="",,B19-A19) -> 7 | L19: =IF(B19="","Listed","Sold") -> Sold | M19: =IF(L19="SOLD",H19/K19,"") -> 19.285714 | O19: =MONTH(B19) -> 11
A20: 45962 | B20: 45967 | C20: cute little table and 4 chairs | D20: 48 | E20: 150 | F20: 140 | G20: =IF(ISNUMBER(H20),0,E20-D20) -> 0 | H20: =IF(F20-D20<-1,"",F20-D20) -> 92 | I20: =G20/E20 -> 0 | J20: =((F20-D20)/F20) -> 0.65714286 | K20: =IF(B20="",,B20-A20) -> 5 | L20: =IF(B20="","Listed","Sold") -> Sold | M20: =IF(L20="SOLD",H20/K20,"") -> 18.4 | O20: =MONTH(B20) -> 11
A21: 45962 | B21: 45969 | C21: mirror | D21: 12 | E21: 100 | F21: 100 | G21: =IF(ISNUMBER(H21),0,E21-D21) -> 0 | H21: =IF(F21-D21<-1,"",F21-D21) -> 88 | I21: =G21/E21 -> 0 | J21: =((F21-D21)/F21) -> 0.88 | K21: =IF(B21="",,B21-A21) -> 7 | L21: =IF(B21="","Listed","Sold") -> Sold | M21: =IF(L21="SOLD",H21/K21,"") -> 12.571429 | O21: =MONTH(B21) -> 11
A22: 45962 | B22: 45969 | C22: golden floral picture | D22: 12 | E22: 50 | F22: 50 | G22: =IF(ISNUMBER(H22),0,E22-D22) -> 0 | H22: =IF(F22-D22<-1,"",F22-D22) -> 38 | I22: =G22/E22 -> 0 | J22: =((F22-D22)/F22) -> 0.76 | K22: =IF(B22="",,B22-A22) -> 7 | L22: =IF(B22="","Listed","Sold") -> Sold | M22: =IF(L22="SOLD",H22/K22,"") -> 5.4285714 | O22: =MONTH(B22) -> 11
A23: 45969 | B23: 45977 | C23: small entry table | D23: 18 | E23: 125 | F23: 80 | G23: =IF(ISNUMBER(H23),0,E23-D23) -> 0 | H23: =IF(F23-D23<-1,"",F23-D23) -> 62 | I23: =G23/E23 -> 0 | J23: =((F23-D23)/F23) -> 0.775 | K23: =IF(B23="",,B23-A23) -> 8 | L23: =IF(B23="","Listed","Sold") -> Sold | M23: =IF(L23="SOLD",H23/K23,"") -> 7.75 | O23: =MONTH(B23) -> 11
A24: 45969 | C24: glass coffee table | D24: 15 | E24: 75 | G24: =IF(ISNUMBER(H24),0,E24-D24) -> 60 | H24: =IF(F24-D24<-1,"",F24-D24) | I24: =G24/E24 -> 0.8 | J24: =((F24-D24)/F24) -> #DIV/0! | K24: =IF(B24="",,B24-A24) -> 0 | L24: =IF(B24="","Listed","Sold") -> Listed | M24: =IF(L24="SOLD",H24/K24,"") | O24: =MONTH(B24) -> 1
A25: 45969 | C25: glass end table | D25: 15 | E25: 75 | G25: =IF(ISNUMBER(H25),0,E25-D25) -> 60 | H25: =IF(F25-D25<-1,"",F25-D25) | I25: =G25/E25 -> 0.8 | J25: =((F25-D25)/F25) -> #DIV/0! | K25: =IF(B25="",,B25-A25) -> 0 | L25: =IF(B25="","Listed","Sold") -> Listed | M25: =IF(L25="SOLD",H25/K25,"") | O25: =MONTH(B25) -> 1
A26: 45969 | B26: 45978 | C26: white round side tables x 2 | D26: 38 | E26: 150 | F26: 100 | G26: =IF(ISNUMBER(H26),0,E26-D26) -> 0 | H26: =IF(F26-D26<-1,"",F26-D26) -> 62 | I26: =G26/E26 -> 0 | J26: =((F26-D26)/F26) -> 0.62 | K26: =IF(B26="",,B26-A26) -> 9 | L26: =IF(B26="","Listed","Sold") -> Sold | M26: =IF(L26="SOLD",H26/K26,"") -> 6.8888889 | O26: =MONTH(B26) -> 11
A27: 45973 | B27: 45974 | C27: Solid Oak Storage Bench | D27: 35 | E27: 200 | F27: 160 | G27: =IF(ISNUMBER(H27),0,E27-D27) -> 0 | H27: =IF(F27-D27<-1,"",F27-D27) -> 125 | I27: =G27/E27 -> 0 | J27: =((F27-D27)/F27) -> 0.78125 | K27: =IF(B27="",,B27-A27) -> 1 | L27: =IF(B27="","Listed","Sold") -> Sold | M27: =IF(L27="SOLD",H27/K27,"") -> 125 | O27: =MONTH(B27) -> 11
A28: 45973 | B28: 45976 | C28: eathen Allen side table | D28: 22 | E28: 100 | F28: 70 | G28: =IF(ISNUMBER(H28),0,E28-D28) -> 0 | H28: =IF(F28-D28<-1,"",F28-D28) -> 48 | I28: =G28/E28 -> 0 | J28: =((F28-D28)/F28) -> 0.68571429 | K28: =IF(B28="",,B28-A28) -> 3 | L28: =IF(B28="","Listed","Sold") -> Sold | M28: =IF(L28="SOLD",H28/K28,"") -> 16 | O28: =MONTH(B28) -> 11
A29: 45975 | B29: 46004 | C29: ikea drop leaf | D29: 45 | E29: 150 | F29: 75 | G29: =IF(ISNUMBER(H29),0,E29-D29) -> 0 | H29: =IF(F29-D29<-1,"",F29-D29) -> 30 | I29: =G29/E29 -> 0 | J29: =((F29-D29)/F29) -> 0.4 | K29: =IF(B29="",,B29-A29) -> 29 | L29: =IF(B29="","Listed","Sold") -> Sold | M29: =IF(L29="SOLD",H29/K29,"") -> 1.0344828 | O29: =MONTH(B29) -> 12
A30: 45975 | B30: 46009 | C30: blue back pack | D30: 3 | E30: 45 | F30: 20 | G30: =IF(ISNUMBER(H30),0,E30-D30) -> 0 | H30: =IF(F30-D30<-1,"",F30-D30) -> 17 | I30: =G30/E30 -> 0 | J30: =((F30-D30)/F30) -> 0.85 | K30: =IF(B30="",,B30-A30) -> 34 | L30: =IF(B30="","Listed","Sold") -> Sold | M30: =IF(L30="SOLD",H30/K30,"") -> 0.5 | O30: =MONTH(B30) -> 12
A31: 45975 | C31: fall picture | D31: 6 | E31: 35 | G31: =IF(ISNUMBER(H31),0,E31-D31) -> 29 | H31: =IF(F31-D31<-1,"",F31-D31) | I31: =G31/E31 -> 0.82857143 | J31: =((F31-D31)/F31) -> #DIV/0! | K31: =IF(B31="",,B31-A31) -> 0 | L31: =IF(B31="","Listed","Sold") -> Listed | M31: =IF(L31="SOLD",H31/K31,"") | O31: =MONTH(B31) -> 1
A32: 45975 | B32: 45986 | C32: cat tree | D32: 0 | E32: 100 | F32: 30 | G32: =IF(ISNUMBER(H32),0,E32-D32) -> 0 | H32: =IF(F32-D32<-1,"",F32-D32) -> 30 | I32: =G32/E32 -> 0 | J32: =((F32-D32)/F32) -> 1 | K32: =IF(B32="",,B32-A32) -> 11 | L32: =IF(B32="","Listed","Sold") -> Sold | M32: =IF(L32="SOLD",H32/K32,"") -> 2.7272727 | O32: =MONTH(B32) -> 11
A33: 45983 | B33: 45984 | C33: antique small wood dresser | D33: 28 | E33: 100 | F33: 80 | G33: =IF(ISNUMBER(H33),0,E33-D33) -> 0 | H33: =IF(F33-D33<-1,"",F33-D33) -> 52 | I33: =G33/E33 -> 0 | J33: =((F33-D33)/F33) -> 0.65 | K33: =IF(B33="",,B33-A33) -> 1 | L33: =IF(B33="","Listed","Sold") -> Sold | M33: =IF(L33="SOLD",H33/K33,"") -> 52 | O33: =MONTH(B33) -> 11
A34: 45983 | B34: 45991 | C34: dresser 7 drawer | D34: 47 | E34: 250 | F34: 275 | G34: =IF(ISNUMBER(H34),0,E34-D34) -> 0 | H34: =IF(F34-D34<-1,"",F34-D34) -> 228 | I34: =G34/E34 -> 0 | J34: =((F34-D34)/F34) -> 0.82909091 | K34: =IF(B34="",,B34-A34) -> 8 | L34: =IF(B34="","Listed","Sold") -> Sold | M34: =IF(L34="SOLD",H34/K34,"") -> 28.5 | O34: =MONTH(B34) -> 11
A35: 45983 | C35: green wood mirror | D35: 8 | E35: 45 | G35: =IF(ISNUMBER(H35),0,E35-D35) -> 37 | H35: =IF(F35-D35<-1,"",F35-D35) | I35: =G35/E35 -> 0.82222222 | J35: =((F35-D35)/F35) -> #DIV/0! | K35: =IF(B35="",,B35-A35) -> 0 | L35: =IF(B35="","Listed","Sold") -> Listed | M35: =IF(L35="SOLD",H35/K35,"") | O35: =MONTH(B35) -> 1
A36: 45983 | B36: 45992 | C36: 3 door wooded side table | D36: 13 | E36: 100 | F36: 85 | G36: =IF(ISNUMBER(H36),0,E36-D36) -> 0 | H36: =IF(F36-D36<-1,"",F36-D36) -> 72 | I36: =G36/E36 -> 0 | J36: =((F36-D36)/F36) -> 0.84705882 | K36: =IF(B36="",,B36-A36) -> 9 | L36: =IF(B36="","Listed","Sold") -> Sold | M36: =IF(L36="SOLD",H36/K36,"") -> 8 | O36: =MONTH(B36) -> 12
A37: 45991 | B37: 45994 | C37: rug 1 | D37: 5 | E37: 120 | F37: 120 | G37: =IF(ISNUMBER(H37),0,E37-D37) -> 0 | H37: =IF(F37-D37<-1,"",F37-D37) -> 115 | I37: =G37/E37 -> 0 | J37: =((F37-D37)/F37) -> 0.95833333 | K37: =IF(B37="",,B37-A37) -> 3 | L37: =IF(B37="","Listed","Sold") -> Sold | M37: =IF(L37="SOLD",H37/K37,"") -> 38.333333 | O37: =MONTH(B37) -> 12
A38: 45991 | B38: 46000 | C38: rug 2 | D38: 15 | E38: 110 | F38: 100 | G38: =IF(ISNUMBER(H38),0,E38-D38) -> 0 | H38: =IF(F38-D38<-1,"",F38-D38) -> 85 | I38: =G38/E38 -> 0 | J38: =((F38-D38)/F38) -> 0.85 | K38: =IF(B38="",,B38-A38) -> 9 | L38: =IF(B38="","Listed","Sold") -> Sold | M38: =IF(L38="SOLD",H38/K38,"") -> 9.4444444 | O38: =MONTH(B38) -> 12
A39: 45991 | B39: 46028 | C39: leather Ottoman | D39: 4 | E39: 40 | F39: 40 | G39: =IF(ISNUMBER(H39),0,E39-D39) -> 0 | H39: =IF(F39-D39<-1,"",F39-D39) -> 36 | I39: =G39/E39 -> 0 | J39: =((F39-D39)/F39) -> 0.9 | K39: =IF(B39="",,B39-A39) -> 37 | L39: =IF(B39="","Listed","Sold") -> Sold | M39: =IF(L39="SOLD",H39/K39,"") -> 0.97297297 | O39: =MONTH(B39) -> 1
A40: 45991 | C40: vanity stool | D40: 6 | E40: 45 | G40: =IF(ISNUMBER(H40),0,E40-D40) -> 39 | H40: =IF(F40-D40<-1,"",F40-D40) | I40: =G40/E40 -> 0.86666667 | J40: =((F40-D40)/F40) -> #DIV/0! | K40: =IF(B40="",,B40-A40) -> 0 | L40: =IF(B40="","Listed","Sold") -> Listed | M40: =IF(L40="SOLD",H40/K40,"") | O40: =MONTH(B40) -> 1
...

Sheet Summary Sheet
A1: Total spent | B1: Total made | C1: Total profit | D1: Predicted profit | E1: Total amt | F1: Current Invested | G1: Total Topline (Predicted+Actual
A2: =SUM(Log!D:D) -> 1107 | B2: =SUM(Log!F:F) -> 5130 | C2: =SUM(Log!H:H) -> 4166 | D2: =SUM(Log!G:G) -> 702 | E2: =C2+D2 -> 4868 | F2: =SUMIF(Log!F:F,"",Log!D:D) -> 143
A5: month | B5: profit that month
A6: 10 | B6: =SUMIF(Log!O:O,A6,Log!H:H) -> 831
A7: 11 | B7: =SUMIF(Log!O:O,A7,Log!H:H) -> 1468
A8: 12 | B8: =SUMIF(Log!O:O,A8,Log!H:H) -> 749
A9: 1 | B9: =SUMIF(Log!O:O,A9,Log!H:H) -> 926
A10: 2 | B10: =SUMIF(Log!O:O,A10,Log!H:H) -> 192
